<mujoco model="biped">
  <compiler angle="radian" meshdir="../meshes" autolimits="true"/>
  <option iterations="3" ls_iterations="5" integrator="Euler">
    <flag eulerdamp="disable"/>
  </option>
  <default/>

  <visual>
    <headlight diffuse=".8 .8 .8" ambient=".2 .2 .2" specular="1 1 1"/>
    <rgba force="1 0 0 1"/>
    <global azimuth="120" elevation="-20"/>
    <map force="0.01"/>
    <scale forcewidth="0.3" contactwidth="0.5" contactheight="0.2"/>
    <quality shadowsize="8192"/>
  </visual>
  <asset>
    <mesh name="base_link" file="base_link.STL"/>
    <mesh name="R_SHOULDER" file="R_SHOULDER.STL"/>
    <mesh name="R_UPPER_LEG" file="R_UPPER_LEG.STL"/>
    <mesh name="R_LOWER_LEG" file="R_LOWER_LEG.STL"/>
    <mesh name="R_FOOT" file="R_FOOT.STL"/>
    <mesh name="L_SHOULDER" file="L_SHOULDER.STL"/>
    <mesh name="L_UPPER_LEG" file="L_UPPER_LEG.STL"/>
    <mesh name="L_LOWER_LEG" file="L_LOWER_LEG.STL"/>
    <mesh name="L_FOOT" file="L_FOOT.STL"/>
    <texture type="skybox" builtin="gradient" rgb1="1 1 1" rgb2="1 1 1" width="800" height="800"/>
    <texture type="2d" name="groundplane" builtin="checker" mark="edge" rgb1="1 1 1" rgb2="1 1 1" markrgb="0 0 0"
      width="300" height="300"/>
    <material name="groundplane" texture="groundplane" texuniform="true" texrepeat="5 5" reflectance="0"/>

  </asset>
      <sensor>
    <gyro name="gyro" site="imu_location_vectornav" />
    <accelerometer name="accelerometer" site="imu_location_vectornav" />
    <velocimeter site="imu_location" name="local_linvel"/>
    <framezaxis objtype="site" objname="imu_location" name="upvector"/>
    <framexaxis objtype="site" objname="imu_location" name="forwardvector"/>
    <framelinvel objtype="site" objname="imu_location" name="global_linvel"/>
    <frameangvel objtype="site" objname="imu_location" name="global_angvel"/>
    <framepos objtype="site" objname="imu_location" name="position"/>
    <framequat objtype="site" objname="imu_location" name="orientation"/>
    <framelinvel objtype="site" objname="l_foot" name="l_foot_global_linvel"/>
    <framelinvel objtype="site" objname="r_foot" name="r_foot_global_linvel"/>
    <framexaxis objtype="site" objname="l_foot" name="l_foot_upvector"/>
    <framexaxis objtype="site" objname="r_foot" name="r_foot_upvector"/>
    <framepos objtype="site" objname="l_foot" name="l_foot_pos"/>
    <framepos objtype="site" objname="r_foot" name="r_foot_pos"/>
    
  </sensor>
  <!-- <equality>
		<weld body1="base_link" solimp="1.0 1.0 1.0" solref="0.06 1"></weld>
	</equality> -->

  <worldbody>
    <geom name="floor" size="0 0 0.01" type="plane" material="groundplane" contype="1" conaffinity="0" priority="1" friction="0.6" condim="3"/>
  
    <camera name="track" pos="1.805 -2.105 1.0" xyaxes="0.814 0.580 0.000 -0.140 0.196 0.971"/>

    <body name="base_link" pos="0.0 0.0 1.0">
    <camera name="front" pos="1.210 -0.435 0.32" xyaxes="0.342 0.940 0.000 -0.321 0.117 0.940" mode="trackcom"/>
    <inertial pos="-0.025692 0 0.025162" quat="1. 0. 0. 0." mass="4.808222" diaginertia="0.056665 0.046196 0.042241" />
    <geom name="base_link" type="mesh" contype="0" conaffinity="0" rgba="1 1 1 1" mesh="base_link"/>
    <joint armature="0" damping="0" limited="false" name="root" pos="0 0 0" stiffness="0" type="free"/>
    <site name="imu_location" pos="0 0 0" euler="0 0 0" size="0.01" type="sphere" rgba="1 0 0 1"/>
    <site name="imu_location_vectornav" pos="0 0 0" euler="-3.141592 0 0" size="0.01" type="sphere" rgba="1 0 0 1"/>

    <body name="L_SHOULDER" pos="0.005 0.07 -0.091">
      <inertial pos="-0.00039 -0.022865 0.000966" quat="0.5 0.5 0.5 0.5" mass="0.52963" diaginertia="0.000691 0.000491 0.000368"/>
      <joint name="L_HAA" pos="0 0 0" axis="1 0 0" range="-0.25 0.25" limited="true"/>
      <geom type="mesh" contype="0" conaffinity="0" rgba="1 1 1 1" mesh="L_SHOULDER"/>

      <body name="L_UPPER_LEG">
        <inertial pos="2.3e-05 0.054429 -0.064678" quat="1 0 0 0" mass="0.958425" diaginertia="0.009526 0.00948302 0.00101198"/>
        <joint name="L_HFE" pos="0 0 0" axis="0 1 0" range="-1.5 1.5" limited="true"/>
        <geom type="mesh" contype="0" conaffinity="0" rgba="1 1 1 1" mesh="L_UPPER_LEG"/>

        <body name="L_LOWER_LEG" pos="0 0.0594 -0.234046">
          <inertial pos="0.000245 -0.019422 -0.122672" mass="0.115744" diaginertia="0.001579 0.001579 2.1e-05"/>
          <joint name="L_KFE" pos="0 0 0" axis="0 1 0" limited="true" range="-2.2 2.2"/>
          <geom type="mesh" contype="0" conaffinity="0" rgba="1 1 1 1" mesh="L_LOWER_LEG"/>

          <body name="L_FOOT" pos="0 -0.01975 -0.3247">
            <inertial pos="-8.2e-05 0 -0.002961" quat="0.5 0.5 0.5 0.5" mass="0.029476" diaginertia="4.8e-05 4.8e-05 1e-06"/>
            <joint name="L_ANKLE" pos="0 0 0" axis="0 1 0" range="-1.6 1.6" limited="true"/>
            <geom type="mesh" contype="0" conaffinity="0" rgba="1 1 1 1" mesh="L_FOOT"/>
            <geom name="L_FOOT" friction="1. 0.3 0.3" size="0.015 0.05" pos="0 0 -0.01" quat="0.710914 0 0.703279 0"  type="capsule" rgba="0.8 0.8 0.8 1"/>
            <site name="l_foot" quat="0.710914 0 0.703279 0"/>
          </body> <!-- L_FOOT -->

        </body> <!-- L_LOWER_LEG -->

      </body> <!-- L_UPPER_LEG -->

    </body> <!-- L_SHOULDER -->

    <body name="R_SHOULDER" pos="0.005 -0.07 -0.091">
      <inertial pos="-0.00039 0.022865 -0.000966" quat="0.5 0.5 0.5 0.5" mass="0.52963" diaginertia="0.000691 0.000491 0.000368"/>
      <joint name="R_HAA" pos="0 0 0" axis="1 0 0" range="-0.25 0.25" limited="true"/>
      <geom type="mesh" contype="0" conaffinity="0" rgba="1 1 1 1" mesh="R_SHOULDER"/>
      <body name="R_UPPER_LEG">
        <inertial pos="-2.3e-05 -0.054429 -0.064678" mass="0.95843" diaginertia="0.009526 0.009483 0.001012"/>
        <joint name="R_HFE" pos="0 0 0" axis="0 1 0" range="-1.5 1.5" limited="true"/>
        <geom type="mesh" contype="0" conaffinity="0" rgba="1 1 1 1" mesh="R_UPPER_LEG"/>

        <body name="R_LOWER_LEG" pos="0 -0.0641789 -0.232529">
          <inertial pos="-0.000245 0.0242 -0.12419" mass="0.11574" diaginertia="0.001579 0.001579 2.1e-05"/>
          <joint name="R_KFE" pos="0 0 0" axis="0 1 0" range="-2.2 2.2" limited="true"/>
          <geom type="mesh" contype="0" conaffinity="0" rgba="1 1 1 1" mesh="R_LOWER_LEG"/>

          <body name="R_FOOT" pos="0 0.0245289 -0.326217">
            <inertial pos="0 0 -0.002962" quat="0.5 0.5 0.5 0.5" mass="0.029476" diaginertia="4.8e-05 4.8e-05 1e-06"/>
            <joint name="R_ANKLE" pos="0 0 0" axis="0 1 0" range="-1.6 1.6" limited="true"/>
            <geom type="mesh" contype="0" conaffinity="0" rgba="1 1 1 1" mesh="R_FOOT"/>
            <geom name="R_FOOT" friction="1. 0.3 0.3" size="0.015 0.05" pos="0 0 -0.01" quat="0.710914 0 0.703279 0"  type="capsule" rgba="0.8 0.8 0.8 1"/>
            <site name="r_foot" quat="0.710914 0 0.703279 0"/>
          </body> <!-- R_FOOT -->

          </body> <!-- R_LOWER_LEG -->
  
        </body> <!-- R_UPPER_LEG -->

      </body> <!-- R_SHOULDER -->

    </body> <!--  base_link -->
  </worldbody>

    <actuator>

      <position name="L_HAA" joint="L_HAA" kp="38.1" kv="3.18"/>
      <position name="L_HFE" joint="L_HFE" kp="38.1" kv="3.18"/>
      <position name="L_KFE" joint="L_KFE" kp="38.1" kv="0.95"/>
      <position name="L_ANKLE" joint="L_ANKLE" kp="0.1" kv="0.005"/>

      <position name="R_HAA" joint="R_HAA" kp="38.1" kv="3.18"/>
      <position name="R_HFE" joint="R_HFE" kp="38.1" kv="3.18"/>
      <position name="R_KFE" joint="R_KFE" kp="38.1" kv="0.95"/>
      <position name="R_ANKLE" joint="R_ANKLE" kp="0.1" kv="0.005"/>

    </actuator>

    <keyframe>
      <key name="home"
          qpos="
        0 0 0.7
        1 0 0 0
        0.0 -0.65 0.983 -0.35
        0.0 -0.65 0.983 -0.35"
          ctrl="
        0.0 -0.65 0.983 -0.35
        0.0 -0.65 0.983 -0.35"/>
  </keyframe>

</mujoco>
