<mujoco model="biped">
  <compiler angle="radian" meshdir="../meshes_v2/" autolimits="true"/>
  <option integrator="RK4"/>
  <default/>
  <asset>
    <mesh name="base_link" file="base_link_v2.STL"/>
    <mesh name="R_HIP" file="R_HIP.STL"/>
    <mesh name="R_SHOULDER" file="R_SHOULDER.STL"/>
    <mesh name="R_UPPER_LEG" file="R_UPPER_LEG.STL"/>
    <mesh name="R_LOWER_LEG" file="R_LOWER_LEG.STL"/>
    <mesh name="R_FOOT" file="R_FOOT.STL"/>
    <mesh name="L_HIP" file="L_HIP.STL"/>
    <mesh name="L_SHOULDER" file="L_SHOULDER.STL"/>
    <mesh name="L_UPPER_LEG" file="L_UPPER_LEG.STL"/>
    <mesh name="L_LOWER_LEG" file="L_LOWER_LEG.STL"/>
    <mesh name="L_FOOT" file="L_FOOT.STL"/>

    <texture type="skybox" builtin="gradient" width="128" height="128" rgb1=".4 .6 .8" rgb2="0 0 0"/>
    
    <hfield name="hill" nrow="400" ncol="400" size="8 8 1 1"/>

    <!-- <hfield name="hill" size = "4 4 0.2 0.5" file="../terrains/test_hills.png"/> -->

    <texture builtin="checker" height="100" name="texplane" rgb1="0.14 0.31 0.27" rgb2="0.47 0.63 0.6" type="2d" width="100"/>
    <material name="MatPlane" reflectance="0.5" shininess="1" specular="1" texrepeat="60 60"  texture="texplane"/>

  </asset>

    <equality>
		<weld body1="base_link" solimp="1.0 1.0 1.0" solref="0.06 1"></weld>
	</equality>

  <sensor>
    <gyro name="gyro" site="imu_location" />
    <accelerometer name="accelerometer" site="imu_location" />
  </sensor>

  <worldbody>
    <light cutoff="100" diffuse="1 1 1" dir="-0 0 -1.3" directional="true" exponent="1" pos="0 0 1.3" specular=".1 .1 .1"/>
    <geom name="floor" friction="1 .1 .1" condim="3" material="MatPlane" pos="0 0 0" rgba="0.8 0.9 0.8 1" size="40 40 0.01" type="plane"/>

    <body name="base_link" pos="0.0 0.0 0.5">
      <inertial pos="-0.022 0 0.068" quat="1. 0. 0. 0." mass="3.272" diaginertia="0.018 0.030 0.026" />
      <geom name="base_link" type="mesh" contype="2" rgba="1 1 1 1" mesh="base_link"/>
      <joint armature="0" damping="0" limited="false" name="root" pos="0 0 0" stiffness="0" type="free"/>
      <site name="imu_location" pos="0 0 0" euler="-3.141592 0 0" size="0.01" type="sphere" rgba="1 0 0 1"/>

      <body name="L_HIP" pos="0 0.07 -0.005">
        <inertial pos="-0.0542 0 -0.072" mass="0.624" diaginertia="0.002 0.001 0.001"/>
        <joint name="L_YAW" pos="0 0 0" axis="0 0 1" limited="true" range="-0.3 0.3"/>
        <geom name="L_HIP" type="mesh" contype="2" rgba="1 1 1 1" mesh="L_HIP"/>

        <body name="L_SHOULDER" pos="0.005 0 -0.086">
          <inertial pos="-0.0020134 0.022813 -0.00077458" quat="1. 0. 0. 0." mass="0.524" diaginertia="0.00068 0.00048 0.0003"/>
          <joint name="L_HAA" pos="0 0 0" axis="1 0 0" limited="true" range="-0.25 0.25"/>
          <geom name="L_SHOULDER" type="mesh" contype="2" rgba="1 0 0 1" mesh="L_SHOULDER"/>

          <body name="L_UPPER_LEG" pos="0 0 0">
            <inertial pos="3.4626e-05 0.058 -0.054" mass="0.88" diaginertia="0.008 0.008 0.001"/>
            <joint name="L_HFE" pos="0 0 0" axis="0 1 0" limited="true" range="-1.5 1.5"/>
            <geom name="L_UPPER_LEG" type="mesh" contype="2"  rgba="1 0 0 1" mesh="L_UPPER_LEG"/>
            
            <body name="L_LOWER_LEG" pos="0 0.0589 -0.23405">
              <inertial pos="-1.356e-05 -0.017 -0.15" mass="0.118" diaginertia="0.00043 0.00043 1.55e-5"/>
              <joint name="L_KFE" pos="0 0 0" axis="0 1 0" limited="true" range="-2.2 -0.1"/>
              <geom name="L_LOWER_LEG" type="mesh" contype="2" rgba="0.792157 0.819608 0.933333 1" mesh="L_LOWER_LEG"/>
              
              <body name="L_FOOT" pos="0.0019 -0.0173 -0.30326">
                <inertial pos="-0.00185 -4.9998e-05 -0.0083528" quat="0.710914 0 0.703279 0" mass="0.03134" diaginertia="3.39896e-05 3.35525e-05 1.53506e-06"/>
                <joint name="L_ANKLE" pos="0 0 0" axis="0 1 0" limited="true" range="-0.7 0.7"/>
                <geom name="L_FOOT" friction="1. 0.3 0.3" size="0.015 0.05" pos="0 0 -0.01" quat="0.710914 0 0.703279 0"  type="capsule" rgba="0.8 0.8 0.8 1" contype="1" conaffinity="1"/>
              </body> <!--  L_FOOT -->
            </body> <!--  L_LOWER_LEG -->
          </body> <!--  L_UPPER_LEG -->
        </body> <!--  L_SHOULDER -->
      </body> <!--  L_HIP -->


      <body name="R_HIP" pos="0 -0.07 -0.005">
        <inertial pos="-0.0542 0 -0.072" mass="0.624" diaginertia="0.002 0.001 0.001"/>
        <joint name="R_YAW" pos="0 0 0" axis="0 0 1" limited="true" range="-0.3 0.3"/>
        <geom name="R_HIP" type="mesh" contype="2" rgba="0.69804 0.69804 0.69804 1" mesh="R_HIP"/>
        
        <body name="R_SHOULDER" pos="0.005 0 -0.086">
          <inertial pos="-0.0020134 0.022813 -0.00077458" quat="1. 0. 0. 0." mass="0.524" diaginertia="0.00068 0.00048 0.0003"/>
          <joint name="R_HAA" pos="0 0 0" axis="1 0 0" limited="true" range="-0.25 0.25"/>
          <geom name="R_SHOULDER" type="mesh" contype="2" rgba="1 0 0 1" mesh="R_SHOULDER"/>
          
          <body name="R_UPPER_LEG" pos="0 0 0">
            <inertial pos="0 -0.058 -0.054" quat="1. 0. 0. 0." mass="0.88" diaginertia="0.008 0.008 0.001"/>
            <joint name="R_HFE" pos="0 0 0" axis="0 1 0" limited="true" range="-1.5 1.5"/>
            <geom name="R_UPPER_LEG" type="mesh" contype="2" rgba="1 0 0 1" mesh="R_UPPER_LEG"/>
            
            <body name="R_LOWER_LEG" pos="0 -0.0584 -0.23405">
              <inertial pos="0 0.017 -0.15" quat="1. 0. 0. 0." mass="0.118" diaginertia="0.00043 0.00043 1.55e-5"/>
              <joint name="R_KFE" pos="0 0 0" axis="0 1 0" limited="true" range="-2.2 -0.1"/>
              <geom name="R_LOWER_LEG" type="mesh" contype="2" rgba="0.792157 0.819608 0.933333 1" mesh="R_LOWER_LEG"/>
              
              <body name="R_FOOT" pos="0.0019 0.0173 -0.30326">
                <inertial pos="-0.00185 4.9998e-05 -0.0083528" quat="0.710914 0 0.703279 0" mass="0.03134" diaginertia="3.39896e-05 3.35525e-05 1.53506e-06"/>
                <joint name="R_ANKLE" pos="0 0 0" axis="0 1 0" limited="true" range="-0.7 0.7"/>
                <geom name="R_FOOT" friction="1. 0.3 0.3" size="0.015 0.05" pos="0 0 -0.01" quat="0.710914 0 0.703279 0"  type="capsule" rgba="0.8 0.8 0.8 1" contype="1" conaffinity="1"/>
              </body> <!--  R_FOOT -->
            </body> <!--  R_LOWER_LEG -->
          </body> <!--  R_UPPER_LEG -->
        </body> <!--  R_SHOULDER -->
      </body> <!--  R_HIP -->

    </body> <!--  base_link -->
  </worldbody>

   <actuator>

        <motor gear="1"  joint="L_YAW" name="L_YAW"/>
            <velocity gear="1" joint="L_YAW" name="L_YAW_VEL" kv="0.5" />

        <motor gear="1"  joint="L_HAA" name="L_HAA"/>
            <velocity gear="1" joint="L_HAA" name="L_HAA_VEL" kv="3.18" />

        <motor gear="1"  joint="L_HFE" name="L_HFE"/>
            <velocity gear="1" joint="L_HFE" name="L_HFE_VEL" kv="3.18" />

        <motor gear="1"  joint="L_KFE" name="L_KFE"/>
            <velocity gear="1" joint="L_KFE" name="L_KFE_VEL" kv="0.95" />

        <motor gear="1"  joint="L_ANKLE" name="L_ANKLE"/>
            <velocity gear="1" joint="L_ANKLE" name="L_ANKLE_VEL" kv="0.005" />

        <motor gear="1"  joint="R_YAW" name="R_YAW"/>
            <velocity gear="1" joint="R_YAW" name="R_YAW_VEL" kv="0.5" />

        <motor gear="1"  joint="R_HAA" name="R_HAA"/>
            <velocity gear="1" joint="R_HAA" name="R_HAA_VEL" kv="3.18" />

        <motor gear="1"  joint="R_HFE" name="R_HFE"/>
            <velocity gear="1" joint="R_HFE" name="R_HFE_VEL" kv="3.18" />

        <motor gear="1"  joint="R_KFE" name="R_KFE"/>
            <velocity gear="1" joint="R_KFE" name="R_KFE_VEL" kv="0.95" />

        <motor gear="1"  joint="R_ANKLE" name="R_ANKLE"/>
            <velocity gear="1" joint="R_ANKLE" name="R_ANKLE_VEL" kv="0.005" />
    </actuator>


</mujoco>
