<mujoco model="pendulum">


  <option iterations="3" ls_iterations="5" timestep="0.001" integrator="Euler">
    <flag eulerdamp="disable"/>
  </option>

  <asset>
    <texture builtin="gradient" height="100" rgb1="1 1 1" rgb2="0 0 0" type="skybox" width="100"/>
    <texture builtin="flat" height="1278" mark="cross" markrgb="1 1 1" name="texgeom" random="0.01" rgb1="0.8 0.6 0.4" rgb2="0.8 0.6 0.4" type="cube" width="127"/>
    <texture builtin="checker" height="100" name="texplane" rgb1="0 0 0" rgb2="0.8 0.8 0.8" type="2d" width="100"/>
    <material name="MatPlane" reflectance="0.5" shininess="1" specular="1" texrepeat="60 60" texture="texplane"/>
    <material name="geom" texture="texgeom" texuniform="true"/>
  </asset>

  <worldbody>
    <light name="light" pos="0 0 2"/>
    <camera name="fixed" pos="0 -1.5 2" xyaxes='1 0 0 0 1 1'/>
    <camera name="lookat" mode="targetbodycom" target="pole" pos="0 -2 1"/>
    <body name="pole" pos="0 0 .6">
      <joint name="hinge" type="hinge" axis="0 1 0" damping="0.1"/>
      <geom name="base" type="cylinder" fromto="0 -.03 0 0 .03 0" size="0.021" mass="0"/>
      <geom name="pole" type="capsule" fromto="0 0 0 0 0 0.5" size="0.02" mass="0"/>
      <geom name="mass" type="sphere" pos="0 0 0.5" size="0.05" mass="1"/>
    </body>
  </worldbody>

  <actuator>
    <motor name="torque" joint="hinge" gear="2" ctrlrange="-2 2" ctrllimited="true"/>
  </actuator>

    <keyframe>
    <key name="home"
      qpos="0"
      qvel="0"
      ctrl="0.0"/>
  </keyframe>

</mujoco>