<mujoco model="ant">
  <compiler angle="degree" coordinate="local" inertiafromgeom="true"/>

  <option iterations="3" ls_iterations="5" timestep="0.001" integrator="Euler">
    <flag eulerdamp="disable"/>
  </option>

  <default>
    <joint armature="1" damping="1" limited="true"/>
    <!-- <geom contype="0" conaffinity="0" condim="3" density="5.0" friction="1 0.5 0.5"
     rgba="0.4 0.33 0.26 1.0"/> -->
  </default>
  <asset>
    <texture builtin="gradient" height="100" rgb1="1 1 1" rgb2="0 0 0" type="skybox" width="100"/>
    <texture builtin="flat" height="1278" mark="cross" markrgb="1 1 1" name="texgeom" random="0.01" rgb1="0.8 0.6 0.4" rgb2="0.8 0.6 0.4" type="cube" width="127"/>
    <texture builtin="checker" height="100" name="texplane" rgb1="0 0 0" rgb2="0.8 0.8 0.8" type="2d" width="100"/>
    <material name="MatPlane" reflectance="0.5" shininess="1" specular="1" texrepeat="60 60" texture="texplane"/>
    <material name="geom" texture="texgeom" texuniform="true"/>
  </asset>
  <sensor>
    <framezaxis objtype="site" objname="imu_location" name="upvector"/>
  </sensor>

   <worldbody>
    <light cutoff="100" diffuse="1 1 1" dir="-0 0 -1.3" directional="true" exponent="1" pos="0 0 1.3" specular=".1 .1 .1"/>
    <geom conaffinity="1" condim="3" material="MatPlane" name="floor" pos="0 0 0" rgba="0.8 0.9 0.8 1" size="40 40 40" type="plane"/>
    <body name="torso" pos="0 0 0.3">
      <camera name="track" mode="trackcom" pos="0 -3 0.3" xyaxes="1 0 0 0 0 1"/>
      <geom name="torso_geom" pos="0 0 0" size="0.075" type="sphere" mass="0.350"/>
      <joint armature="0" damping="0" limited="false" margin="0.01" name="root" pos="0 0 0" type="free"/>
      <site name="imu_location" pos="0 0 0" euler="0 0 0" size="0.01" type="sphere" rgba="1 0 0 1"/>

      <body name="front_left_leg" pos="0 0 0">
        <geom fromto="0.0 0.0 0.0 0.06 0.06 0.0" name="aux_1_geom" size="0.024" type="capsule" mass="0.020"/>
        <body name="aux_1" pos="0.06 0.06 0">
          <joint axis="0 0 1" name="hip_1" pos="0.0 0.0 0.0" range="-30 30" type="hinge"/>
          <geom fromto="0.0 0.0 0.0 0.06 0.06 0.0" name="left_leg_geom" size="0.024" type="capsule" mass="0.080"/>
          <body pos="0.06 0.06 0">
            <joint axis="-1 1 0" name="ankle_1" pos="0.0 0.0 0.0" range="30 70" type="hinge"/>
            <geom fromto="0.0 0.0 0.0 0.12 0.12 0.0" name="left_ankle_geom" size="0.024" type="capsule" mass="0.030"/>
          </body>
        </body>
      </body>
      <body name="front_right_leg" pos="0 0 0">
        <geom fromto="0.0 0.0 0.0 -0.06 0.06 0.0" name="aux_2_geom" size="0.024" type="capsule" mass="0.020"/>
        <body name="aux_2" pos="-0.06 0.06 0">
          <joint axis="0 0 1" name="hip_2" pos="0.0 0.0 0.0" range="-30 30" type="hinge"/>
          <geom fromto="0.0 0.0 0.0 -0.06 0.06 0.0" name="right_leg_geom" size="0.024" type="capsule" mass="0.080"/>
          <body pos="-0.06 0.06 0">
            <joint axis="1 1 0" name="ankle_2" pos="0.0 0.0 0.0" range="-70 -30" type="hinge"/>
            <geom fromto="0.0 0.0 0.0 -0.12 0.12 0.0" name="right_ankle_geom" size="0.024" type="capsule" mass="0.030"/>
          </body>
        </body>
      </body>
      <body name="back_leg" pos="0 0 0">
        <geom fromto="0.0 0.0 0.0 -0.06 -0.06 0.0" name="aux_3_geom" size="0.024" type="capsule" mass="0.020"/>
        <body name="aux_3" pos="-0.06 -0.06 0">
          <joint axis="0 0 1" name="hip_3" pos="0.0 0.0 0.0" range="-30 30" type="hinge"/>
          <geom fromto="0.0 0.0 0.0 -0.06 -0.06 0.0" name="back_leg_geom" size="0.024" type="capsule" mass="0.080"/>
          <body pos="-0.06 -0.06 0">
            <joint axis="-1 1 0" name="ankle_3" pos="0.0 0.0 0.0" range="-70 -30" type="hinge"/>
            <geom fromto="0.0 0.0 0.0 -0.12 -0.12 0.0" name="third_ankle_geom" size="0.024" type="capsule" mass="0.030"/>
          </body>
        </body>
      </body>
      <body name="right_back_leg" pos="0 0 0">
        <geom fromto="0.0 0.0 0.0 0.06 -0.06 0.0" name="aux_4_geom" size="0.024" type="capsule" mass="0.020"/>
        <body name="aux_4" pos="0.06 -0.06 0">
          <joint axis="0 0 1" name="hip_4" pos="0.0 0.0 0.0" range="-30 30" type="hinge"/>
          <geom fromto="0.0 0.0 0.0 0.06 -0.06 0.0" name="rightback_leg_geom" size="0.024" type="capsule" mass="0.080"/>
          <body pos="0.06 -0.06 0">
            <joint axis="1 1 0" name="ankle_4" pos="0.0 0.0 0.0" range="30 70" type="hinge"/>
            <geom fromto="0.0 0.0 0.0 0.12 -0.12 0.0" name="fourth_ankle_geom" size="0.024" type="capsule" mass="0.030"/>
          </body>
        </body>
      </body>
    </body>
  </worldbody>
  <actuator>
    <position ctrllimited="true" ctrlrange="-30 30" joint="hip_1" kp="1000" kv="10"/>
    <position ctrllimited="true" ctrlrange="-30 70" joint="ankle_1" kp="5000" kv="200"/>
    <position ctrllimited="true" ctrlrange="-30 30" joint="hip_2" kp="1000" kv="10"/>
    <position ctrllimited="true" ctrlrange="-30 70" joint="ankle_2" kp="5000" kv="200"/>
    <position ctrllimited="true" ctrlrange="-30 30" joint="hip_3" kp="1000" kv="10"/>
    <position ctrllimited="true" ctrlrange="-30 70" joint="ankle_3" kp="5000" kv="200"/>
    <position ctrllimited="true" ctrlrange="-30 30" joint="hip_4" kp="1000" kv="10"/>
    <position ctrllimited="true" ctrlrange="-30 70" joint="ankle_4" kp="5000" kv="200"/>
  </actuator>

    <keyframe>
    <key name="home"
      qpos="
    0 0 0.3
    1 0 0 0
    0.0 0.0 0.0 0.0
    0.0 0.0 0.0 0.0"
      ctrl="
    0.0 0.0 0.0 0.0
    0.0 0.0 0.0 0.0"/>
  </keyframe>

</mujoco>
